Workbook

Sheet V25
A1: RANKING-APP
C3: vecka 25
C4: Vecka 25 | I4: 25 | J4: mot historik
A5: 1 | C5: Gavel 1 | D5: Vara | E5: Ant | F5: Förs | G5: BV | H5: B% | I5: idx antal | J5: idx förs | K5: idx BV
B6: 101625435 | C6: g11 | D6: A+ TVÄTTMEDELCHERRYBLOSSO | E6: 170 | F6: 12229.6 | G6: 3049.6 | H6: =IFERROR(G6/F6,"") -> 0.2493622
C7: g12
C8: g13
C9: g14
C10: total | E10: =SUM(E6:E9) -> 170 | F10: =SUM(F6:F9) -> 12229.6 | G10: =SUM(G6:G9) -> 3049.6 | H10: =IFERROR(G10/F10,"") -> 0.2493622
B11: diff föreg V
B12: index | E12: =E10/$B$112 -> 0.0092230903 | F12: =F10/$B$112 -> 0.66349826 | G12: =G10/$B$112 -> 0.16545139
B13: index diff %
B14: Prestations Index | H14: =IFERROR((G14*0.6)+(F14*0.4),"") -> 0
A15: 2 | C15: Gavel 2 | D15: Vara | E15: Ant | F15: Förs | G15: BV | H15: B% | I15: idx antal | J15: idx förs | K15: idx BV
B16: KOMBI: 101595376 101595377 101595375 101547828 | C16: g21 | D16: CIF spray 750ml | E16: 149 | F16: 3131.22 | G16: 716.76 | H16: =IFERROR(G16/F16,"") -> 0.22890758
C17: g22
C18: g23
C19: g24
C20: total | E20: =SUM(E16:E19) -> 149 | F20: =SUM(F16:F19) -> 3131.22 | G20: =SUM(G16:G19) -> 716.76 | H20: =IFERROR(G20/F20,"") -> 0.22890758
B21: diff föreg V
B22: index | E22: =E20/$B$112 -> 0.0080837674 | F22: =F20/$B$112 -> 0.16987956 | G22: =G20/$B$112 -> 0.038886719
B23: index diff %
B24: Prestations Index | H24: =IFERROR((G24*0.6)+(F24*0.4),"") -> 0
A25: 3 | C25: Gavel 3 | D25: Vara | E25: Ant | F25: Förs | G25: BV | H25: B% | I25: idx antal | J25: idx förs | K25: idx BV
B26: 101648059 | C26: g31 | D26: PK SOF SKÖLJ OUTDFR1300ML | E26: 689 | F26: 16279.16 | G26: 3572.24 | H26: =IFERROR(G26/F26,"") -> 0.21943638
C27: g32
C28: g33
C29: g34
C30: total | E30: =SUM(E26:E29) -> 689 | F30: =SUM(F26:F29) -> 16279.16 | G30: =SUM(G26:G29) -> 3572.24 | H30: =IFERROR(G30/F30,"") -> 0.21943638
B31: diff föreg V
B32: index | E32: =E30/$B$112 -> 0.037380642 | F32: =F30/$B$112 -> 0.88320095 | G32: =G30/$B$112 -> 0.19380642
B33: index diff %
B34: Prestations Index | H34: =IFERROR((G34*0.6)+(F34*0.4),"") -> 0
A35: 4 | C35: Gavel 4 | D35: Vara | E35: Ant | F35: Förs | G35: BV | H35: B% | I35: idx antal | J35: idx förs | K35: idx BV
B36: KOMBI: 101648050 101625436 | C36: g41 | D36: Softlan Appear & Van | E36: 544 | F36: 12850.56 | G36: 2883 | H36: =IFERROR(G36/F36,"") -> 0.2243482
C37: g42
C38: g43
C39: g44
C40: total | E40: =SUM(E36:E39) -> 544 | F40: =SUM(F36:F39) -> 12850.56 | G40: =SUM(G36:G39) -> 2883 | H40: =IFERROR(G40/F40,"") -> 0.2243482
B41: diff föreg V
...

Sheet V26
A1: RANKING-APP
C3: vecka 26
C4: Vecka 26 | I4: 26 | J4: mot historik
A5: 1 | C5: Gavel 1 | D5: Vara | E5: Ant | F5: Förs | G5: BV | H5: B% | I5: idx antal | J5: idx förs | K5: idx BV
B6: 101625435 | C6: g11 | D6: A+ TVÄTTMEDELCHERRYBLOSSO | E6: 172 | F6: 12373.52 | G6: 3085.52 | H6: =IFERROR(G6/F6,"") -> 0.24936477 | I6: =IFERROR(((E6/$B$112) / AVERAGE('V25'!E6/'V25'!$B$112)) * 100,"") -> 103.33489 | J6: =IFERROR(((F6/$B$112) / AVERAGE('V25'!F6/'V25'!$B$112)) * 100,"") -> 103.33524 | K6: =IFERROR(((G6/$B$112) / AVERAGE('V25'!G6/'V25'!$B$112)) * 100,"") -> 103.33631
C7: g12
C8: g13
C9: g14
C10: total | E10: =SUM(E6:E9) -> 172 | F10: =SUM(F6:F9) -> 12373.52 | G10: =SUM(G6:G9) -> 3085.52 | H10: =IFERROR(G10/F10,"") -> 0.24936477
B11: diff föreg V | E11: =IFERROR((E10-('V25'!E10))/('V25'!E10),"") -> 0.011764706 | F11: =IFERROR((F10-('V25'!F10))/('V25'!F10),"") -> 0.011768169 | G11: =IFERROR((G10-('V25'!G10))/('V25'!G10),"") -> 0.011778594 | H11: =IFERROR(H10-('V25'!H10),"") -> 2.569335e-06
B12: index | E12: =E10/$B$112 -> 0.0095306699 | F12: =F10/$B$112 -> 0.68562753 | G12: =G10/$B$112 -> 0.17097135
B13: index diff % | E13: =IFERROR((E12-'V25'!E12)/'V25'!E12,"") -> 0.03334887 | F13: =IFERROR((F12-'V25'!F12)/'V25'!F12,"") -> 0.033352407 | G13: =IFERROR((G12-'V25'!G12)/'V25'!G12,"") -> 0.033363054
B14: Prestations Index | E14: =(E12 / AVERAGE('V25'!E12)) * 100 -> 103.33489 | F14: =(F12 / AVERAGE('V25'!F12)) * 100 -> 103.33524 | G14: =(G12 / AVERAGE('V25'!G12)) * 100 -> 103.33631 | H14: =IFERROR((G14*0.6)+(F14*0.4),"") -> 103.33588
A15: 2 | C15: Gavel 2 | D15: Vara | E15: Ant | F15: Förs | G15: BV | H15: B% | I15: idx antal | J15: idx förs | K15: idx BV
B16: KOMBI: 101595376 101595377 101595375 101547828 | C16: g21 | D16: CIF spray 750ml | E16: 157 | F16: 3133.72 | G16: 629.57 | H16: =IFERROR(G16/F16,"") -> 0.2009018 | I16: =IFERROR(((E16/$B$112) / AVERAGE('V25'!E16/'V25'!$B$112)) * 100,"") -> 107.61699 | J16: =IFERROR(((F16/$B$112) / AVERAGE('V25'!F16/'V25'!$B$112)) * 100,"") -> 102.21486 | K16: =IFERROR(((G16/$B$112) / AVERAGE('V25'!G16/'V25'!$B$112)) * 100,"") -> 89.70935
C17: g22
C18: g23
C19: g24
C20: total | E20: =SUM(E16:E19) -> 157 | F20: =SUM(F16:F19) -> 3133.72 | G20: =SUM(G16:G19) -> 629.57 | H20: =IFERROR(G20/F20,"") -> 0.2009018
B21: diff föreg V | E21: =IFERROR((E20-('V25'!E20))/('V25'!E20),"") -> 0.053691275 | F21: =IFERROR((F20-('V25'!F20))/('V25'!F20),"") -> 0.00079841084 | G21: =IFERROR((G20-('V25'!G20))/('V25'!G20),"") -> -0.12164462 | H21: =IFERROR(H20-('V25'!H20),"") -> -0.028005779
B22: index | E22: =E20/$B$112 -> 0.0086995068 | F22: =F20/$B$112 -> 0.17364216 | G22: =G20/$B$112 -> 0.034885022
B23: index diff % | E23: =IFERROR((E22-'V25'!E22)/'V25'!E22,"") -> 0.076169867 | F23: =IFERROR((F22-'V25'!F22)/'V25'!F22,"") -> 0.022148629 | G23: =IFERROR((G22-'V25'!G22)/'V25'!G22,"") -> -0.1029065
B24: Prestations Index | E24: =(E22 / AVERAGE('V25'!E22)) * 100 -> 107.61699 | F24: =(F22 / AVERAGE('V25'!F22)) * 100 -> 102.21486 | G24: =(G22 / AVERAGE('V25'!G22)) * 100 -> 89.70935 | H24: =IFERROR((G24*0.6)+(F24*0.4),"") -> 94.711555
A25: 3 | C25: Gavel 3 | D25: Vara | E25: Ant | F25: Förs | G25: BV | H25: B% | I25: idx antal | J25: idx förs | K25: idx BV
B26: 101648059 | C26: g31 | D26: PK SOF SKÖLJ OUTDFR1300ML | E26: 351 | F26: 8291.38 | G26: 1844.02 | H26: =IFERROR(G26/F26,"") -> 0.22240206 | I26: =IFERROR(((E26/$B$112) / AVERAGE('V25'!E26/'V25'!$B$112)) * 100,"") -> 52.030181 | J26: =IFERROR(((F26/$B$112) / AVERAGE('V25'!F26/'V25'!$B$112)) * 100,"") -> 52.019033 | K26: =IFERROR(((G26/$B$112) / AVERAGE('V25'!G26/'V25'!$B$112)) * 100,"") -> 52.722069
C27: g32
C28: g33
C29: g34
C30: total | E30: =SUM(E26:E29) -> 351 | F30: =SUM(F26:F29) -> 8291.38 | G30: =SUM(G26:G29) -> 1844.02 | H30: =IFERROR(G30/F30,"") -> 0.22240206
B31: diff föreg V | E31: =IFERROR((E30-('V25'!E30))/('V25'!E30),"") -> -0.49056604 | F31: =IFERROR((F30-('V25'!F30))/('V25'!F30),"") -> -0.49067519 | G31: =IFERROR((G30-('V25'!G30))/('V25'!G30),"") -> -0.48379168 | H31: =IFERROR(H30-('V25'!H30),"") -> 0.0029656772
B32: index | E32: =E30/$B$112 -> 0.019449216 | F32: =F30/$B$112 -> 0.45943259 | G32: =G30/$B$112 -> 0.10217876
B33: index diff % | E33: =IFERROR((E32-'V25'!E32)/'V25'!E32,"") -> -0.47969819 | F33: =IFERROR((F32-'V25'!F32)/'V25'!F32,"") -> -0.47980967 | G33: =IFERROR((G32-'V25'!G32)/'V25'!G32,"") -> -0.47277931
B34: Prestations Index | E34: =(E32 / AVERAGE('V25'!E32)) * 100 -> 52.030181 | F34: =(F32 / AVERAGE('V25'!F32)) * 100 -> 52.019033 | G34: =(G32 / AVERAGE('V25'!G32)) * 100 -> 52.722069 | H34: =IFERROR((G34*0.6)+(F34*0.4),"") -> 52.440854
A35: 4 | C35: Gavel 4 | D35: Vara | E35: Ant | F35: Förs | G35: BV | H35: B% | I35: idx antal | J35: idx förs | K35: idx BV
B36: KOMBI: 101648050 101625436 | C36: g41 | D36: Softlan Appear & Van | E36: 481 | F36: 11364.18 | G36: 2507.52 | H36: =IFERROR(G36/F36,"") -> 0.2206512 | I36: =IFERROR(((E36/$B$112) / AVERAGE('V25'!E36/'V25'!$B$112)) * 100,"") -> 90.305379 | J36: =IFERROR(((F36/$B$112) / AVERAGE('V25'!F36/'V25'!$B$112)) * 100,"") -> 90.319909 | K36: =IFERROR(((G36/$B$112) / AVERAGE('V25'!G36/'V25'!$B$112)) * 100,"") -> 88.831543
C37: g42
C38: g43
C39: g44
C40: total | E40: =SUM(E36:E39) -> 481 | F40: =SUM(F36:F39) -> 11364.18 | G40: =SUM(G36:G39) -> 2507.52 | H40: =IFERROR(G40/F40,"") -> 0.2206512
B41: diff föreg V | E41: =IFERROR((E40-('V25'!E40))/('V25'!E40),"") -> -0.11580882 | F41: =IFERROR((F40-('V25'!F40))/('V25'!F40),"") -> -0.11566655 | G41: =IFERROR((G40-('V25'!G40))/('V25'!G40),"") -> -0.13023933 | H41: =IFERROR(H40-('V25'!H40),"") -> -0.0036969956
...

Sheet V27
A1: RANKING-APP
C3: vecka 27
C4: Vecka 27 | I4: 27 | J4: mot historik
A5: 1 | C5: Gavel 1 | D5: Vara | E5: Ant | F5: Förs | G5: BV | H5: B% | I5: idx antal | J5: idx förs | K5: idx BV
B6: KOMBI: 101896068 101896037 101625435 | C6: g11 | D6: A+ Cherry blossom & Viking vivid&sens 2700ml | E6: 80 | F6: 5670.4 | G6: 918.4 | H6: =IFERROR(G6/F6,"") -> 0.16196388 | I6: =IFERROR(((E6/$B$112) / AVERAGE('V25'!E6/'V25'!$B$112, 'V26'!E6/'V26'!$B$112)) * 100,"") -> 44.419339 | J6: =IFERROR(((F6/$B$112) / AVERAGE('V25'!F6/'V25'!$B$112, 'V26'!F6/'V26'!$B$112)) * 100,"") -> 43.765481 | K6: =IFERROR(((G6/$B$112) / AVERAGE('V25'!G6/'V25'!$B$112, 'V26'!G6/'V26'!$B$112)) * 100,"") -> 28.426081
C7: g12
C8: g13
C9: g14
C10: total | E10: =SUM(E6:E9) -> 80 | F10: =SUM(F6:F9) -> 5670.4 | G10: =SUM(G6:G9) -> 918.4 | H10: =IFERROR(G10/F10,"") -> 0.16196388
B11: diff föreg V | E11: =IFERROR((E10-('V26'!E10))/('V26'!E10),"") -> -0.53488372 | F11: =IFERROR((F10-('V26'!F10))/('V26'!F10),"") -> -0.54173105 | G11: =IFERROR((G10-('V26'!G10))/('V26'!G10),"") -> -0.70235163 | H11: =IFERROR(H10-('V26'!H10),"") -> -0.08740089
B12: index | E12: =E10/$B$112 -> 0.0041651481 | F12: =F10/$B$112 -> 0.2952257 | G12: =G10/$B$112 -> 0.0478159
B13: index diff % | E13: =IFERROR((E12-'V26'!E12)/'V26'!E12,"") -> -0.56297425 | F13: =IFERROR((F12-'V26'!F12)/'V26'!F12,"") -> -0.56940804 | G13: =IFERROR((G12-'V26'!G12)/'V26'!G12,"") -> -0.720328
B14: Prestations Index | E14: =(E12 / AVERAGE('V25'!E12,'V26'!E12)) * 100 -> 44.419339 | F14: =(F12 / AVERAGE('V25'!F12,'V26'!F12)) * 100 -> 43.765481 | G14: =(G12 / AVERAGE('V25'!G12,'V26'!G12)) * 100 -> 28.426081 | H14: =IFERROR((G14*0.6)+(F14*0.4),"") -> 34.561841
A15: 2 | C15: Gavel 2 | D15: Vara | E15: Ant | F15: Förs | G15: BV | H15: B% | I15: idx antal | J15: idx förs | K15: idx BV
B16: KOMBI: 101595376 101595377 101595375 101547828 | C16: g21 | D16: CIF spray 750ml | E16: 180 | F16: 3590.81 | G16: 719.81 | H16: =IFERROR(G16/F16,"") -> 0.20045895 | I16: =IFERROR(((E16/$B$112) / AVERAGE('V25'!E16/'V25'!$B$112, 'V26'!E16/'V26'!$B$112)) * 100,"") -> 111.67765 | J16: =IFERROR(((F16/$B$112) / AVERAGE('V25'!F16/'V25'!$B$112, 'V26'!F16/'V26'!$B$112)) * 100,"") -> 108.84505 | K16: =IFERROR(((G16/$B$112) / AVERAGE('V25'!G16/'V25'!$B$112, 'V26'!G16/'V26'!$B$112)) * 100,"") -> 101.60107
C17: g22
C18: g23
C19: g24
C20: total | E20: =SUM(E16:E19) -> 180 | F20: =SUM(F16:F19) -> 3590.81 | G20: =SUM(G16:G19) -> 719.81 | H20: =IFERROR(G20/F20,"") -> 0.20045895
B21: diff föreg V | E21: =IFERROR((E20-('V26'!E20))/('V26'!E20),"") -> 0.14649682 | F21: =IFERROR((F20-('V26'!F20))/('V26'!F20),"") -> 0.14586179 | G21: =IFERROR((G20-('V26'!G20))/('V26'!G20),"") -> 0.14333593 | H21: =IFERROR(H20-('V26'!H20),"") -> -0.00044285423
B22: index | E22: =E20/$B$112 -> 0.0093715833 | F22: =F20/$B$112 -> 0.18695319 | G22: =G20/$B$112 -> 0.037476441
B23: index diff % | E23: =IFERROR((E22-'V26'!E22)/'V26'!E22,"") -> 0.077254544 | F23: =IFERROR((F22-'V26'!F22)/'V26'!F22,"") -> 0.076657868 | G23: =IFERROR((G22-'V26'!G22)/'V26'!G22,"") -> 0.074284557
B24: Prestations Index | E24: =(E22 / AVERAGE('V25'!E22,'V26'!E22)) * 100 -> 111.67765 | F24: =(F22 / AVERAGE('V25'!F22,'V26'!F22)) * 100 -> 108.84505 | G24: =(G22 / AVERAGE('V25'!G22,'V26'!G22)) * 100 -> 101.60107 | H24: =IFERROR((G24*0.6)+(F24*0.4),"") -> 104.49867
A25: 3 | C25: Gavel 3 | D25: Vara | E25: Ant | F25: Förs | G25: BV | H25: B% | I25: idx antal | J25: idx förs | K25: idx BV
B26: 101648059 | C26: g31 | D26: PK SOF SKÖLJ OUTDFR1300ML | E26: 518 | F26: 12237.04 | G26: 2668.18 | H26: =IFERROR(G26/F26,"") -> 0.21804129 | I26: =IFERROR(((E26/$B$112) / AVERAGE('V25'!E26/'V25'!$B$112, 'V26'!E26/'V26'!$B$112)) * 100,"") -> 94.912551 | J26: =IFERROR(((F26/$B$112) / AVERAGE('V25'!F26/'V25'!$B$112, 'V26'!F26/'V26'!$B$112)) * 100,"") -> 94.905055 | K26: =IFERROR(((G26/$B$112) / AVERAGE('V25'!G26/'V25'!$B$112, 'V26'!G26/'V26'!$B$112)) * 100,"") -> 93.867579
C27: g32
C28: g33
C29: g34
C30: total | E30: =SUM(E26:E29) -> 518 | F30: =SUM(F26:F29) -> 12237.04 | G30: =SUM(G26:G29) -> 2668.18 | H30: =IFERROR(G30/F30,"") -> 0.21804129
B31: diff föreg V | E31: =IFERROR((E30-('V26'!E30))/('V26'!E30),"") -> 0.47578348 | F31: =IFERROR((F30-('V26'!F30))/('V26'!F30),"") -> 0.47587494 | G31: =IFERROR((G30-('V26'!G30))/('V26'!G30),"") -> 0.44693658 | H31: =IFERROR(H30-('V26'!H30),"") -> -0.0043607699
B32: index | E32: =E30/$B$112 -> 0.026969334 | F32: =F30/$B$112 -> 0.63711355 | G32: =G30/$B$112 -> 0.13891706
B33: index diff % | E33: =IFERROR((E32-'V26'!E32)/'V26'!E32,"") -> 0.38665405 | F33: =IFERROR((F32-'V26'!F32)/'V26'!F32,"") -> 0.38674 | G33: =IFERROR((G32-'V26'!G32)/'V26'!G32,"") -> 0.35954936
B34: Prestations Index | E34: =(E32 / AVERAGE('V25'!E32,'V26'!E32)) * 100 -> 94.912551 | F34: =(F32 / AVERAGE('V25'!F32,'V26'!F32)) * 100 -> 94.905055 | G34: =(G32 / AVERAGE('V25'!G32,'V26'!G32)) * 100 -> 93.867579 | H34: =IFERROR((G34*0.6)+(F34*0.4),"") -> 94.28257
A35: 4 | C35: Gavel 4 | D35: Vara | E35: Ant | F35: Förs | G35: BV | H35: B% | I35: idx antal | J35: idx förs | K35: idx BV
B36: KOMBI: 101648050 101625436 | C36: g41 | D36: Softlan Appear & Van | E36: 434 | F36: 10251.24 | G36: 2277.54 | H36: =IFERROR(G36/F36,"") -> 0.22217215 | I36: =IFERROR(((E36/$B$112) / AVERAGE('V25'!E36/'V25'!$B$112, 'V26'!E36/'V26'!$B$112)) * 100,"") -> 80.460493 | J36: =IFERROR(((F36/$B$112) / AVERAGE('V25'!F36/'V25'!$B$112, 'V26'!F36/'V26'!$B$112)) * 100,"") -> 80.447591 | K36: =IFERROR(((G36/$B$112) / AVERAGE('V25'!G36/'V25'!$B$112, 'V26'!G36/'V26'!$B$112)) * 100,"") -> 80.295231
C37: g42
C38: g43
C39: g44
C40: total | E40: =SUM(E36:E39) -> 434 | F40: =SUM(F36:F39) -> 10251.24 | G40: =SUM(G36:G39) -> 2277.54 | H40: =IFERROR(G40/F40,"") -> 0.22217215
B41: diff föreg V | E41: =IFERROR((E40-('V26'!E40))/('V26'!E40),"") -> -0.097713098 | F41: =IFERROR((F40-('V26'!F40))/('V26'!F40),"") -> -0.097934035 | G41: =IFERROR((G40-('V26'!G40))/('V26'!G40),"") -> -0.091716118 | H41: =IFERROR(H40-('V26'!H40),"") -> 0.0015209429
...

Sheet V28
A1: RANKING-APP
C3: vecka 28
C4: Vecka 28 | I4: 28 | J4: mot historik
A5: 1 | C5: Gavel 1 | D5: Vara | E5: Ant | F5: Förs | G5: BV | H5: B% | I5: idx antal | J5: idx förs | K5: idx BV
B6: KOMBI: 101896068 101896037 | C6: g11 | D6: Viking vivid&sens 2700ml | E6: 52 | F6: 3658.72 | G6: 738.72 | H6: =IFERROR(G6/F6,"") -> 0.20190668 | I6: =IFERROR(((E6/$B$112) / AVERAGE('V25'!E6/'V25'!$B$112, 'V26'!E6/'V26'!$B$112, 'V27'!E6/'V27'!$B$112)) * 100,"") -> 34.702799 | J6: =IFERROR(((F6/$B$112) / AVERAGE('V25'!F6/'V25'!$B$112, 'V26'!F6/'V26'!$B$112, 'V27'!F6/'V27'!$B$112)) * 100,"") -> 34.032167 | K6: =IFERROR(((G6/$B$112) / AVERAGE('V25'!G6/'V25'!$B$112, 'V26'!G6/'V26'!$B$112, 'V27'!G6/'V27'!$B$112)) * 100,"") -> 29.405861
C7: g12
C8: g13
C9: g14
C10: total | E10: =SUM(E6:E9) -> 52 | F10: =SUM(F6:F9) -> 3658.72 | G10: =SUM(G6:G9) -> 738.72 | H10: =IFERROR(G10/F10,"") -> 0.20190668
B11: diff föreg V | E11: =IFERROR((E10-('V27'!E10))/('V27'!E10),"") -> -0.35 | F11: =IFERROR((F10-('V27'!F10))/('V27'!F10),"") -> -0.35476862 | G11: =IFERROR((G10-('V27'!G10))/('V27'!G10),"") -> -0.1956446 | H11: =IFERROR(H10-('V27'!H10),"") -> 0.039942795
B12: index | E12: =E10/$B$112 -> 0.0026511675 | F12: =F10/$B$112 -> 0.18653615 | G12: =G10/$B$112 -> 0.037662894
B13: index diff % | E13: =IFERROR((E12-'V27'!E12)/'V27'!E12,"") -> -0.36348781 | F13: =IFERROR((F12-'V27'!F12)/'V27'!F12,"") -> -0.36815749 | G13: =IFERROR((G12-'V27'!G12)/'V27'!G12,"") -> -0.21233536
B14: Prestations Index | E14: =(E12 / AVERAGE('V25'!E12,'V26'!E12,'V27'!E12)) * 100 -> 34.702799 | F14: =(F12 / AVERAGE('V25'!F12,'V26'!F12,'V27'!F12)) * 100 -> 34.032167 | G14: =(G12 / AVERAGE('V25'!G12,'V26'!G12,'V27'!G12)) * 100 -> 29.405861 | H14: =IFERROR((G14*0.6)+(F14*0.4),"") -> 31.256383
A15: 2 | C15: Gavel 2 | D15: Vara | E15: Ant | F15: Förs | G15: BV | H15: B% | I15: idx antal | J15: idx förs | K15: idx BV
B16: KOMBI: 101595376 101595377 101595375 101547828 | C16: g21 | D16: CIF spray 750ml | E16: 197 | F16: 3929.12 | G16: 786.97 | H16: =IFERROR(G16/F16,"") -> 0.20029167 | I16: =IFERROR(((E16/$B$112) / AVERAGE('V25'!E16/'V25'!$B$112, 'V26'!E16/'V26'!$B$112, 'V27'!E16/'V27'!$B$112)) * 100,"") -> 115.20437 | J16: =IFERROR(((F16/$B$112) / AVERAGE('V25'!F16/'V25'!$B$112, 'V26'!F16/'V26'!$B$112, 'V27'!F16/'V27'!$B$112)) * 100,"") -> 113.28842 | K16: =IFERROR(((G16/$B$112) / AVERAGE('V25'!G16/'V25'!$B$112, 'V26'!G16/'V26'!$B$112, 'V27'!G16/'V27'!$B$112)) * 100,"") -> 108.19828
C17: g22
C18: g23
C19: g24
C20: total | E20: =SUM(E16:E19) -> 197 | F20: =SUM(F16:F19) -> 3929.12 | G20: =SUM(G16:G19) -> 786.97 | H20: =IFERROR(G20/F20,"") -> 0.20029167
B21: diff föreg V | E21: =IFERROR((E20-('V27'!E20))/('V27'!E20),"") -> 0.094444444 | F21: =IFERROR((F20-('V27'!F20))/('V27'!F20),"") -> 0.094215511 | G21: =IFERROR((G20-('V27'!G20))/('V27'!G20),"") -> 0.093302399 | H21: =IFERROR(H20-('V27'!H20),"") -> -0.00016728101
B22: index | E22: =E20/$B$112 -> 0.010043846 | F22: =F20/$B$112 -> 0.20032222 | G22: =G20/$B$112 -> 0.040122871
B23: index diff % | E23: =IFERROR((E22-'V27'!E22)/'V27'!E22,"") -> 0.071734192 | F23: =IFERROR((F22-'V27'!F22)/'V27'!F22,"") -> 0.071510009 | G23: =IFERROR((G22-'V27'!G22)/'V27'!G22,"") -> 0.070615845
B24: Prestations Index | E24: =(E22 / AVERAGE('V25'!E22,'V26'!E22,'V27'!E22)) * 100 -> 115.20437 | F24: =(F22 / AVERAGE('V25'!F22,'V26'!F22,'V27'!F22)) * 100 -> 113.28842 | G24: =(G22 / AVERAGE('V25'!G22,'V26'!G22,'V27'!G22)) * 100 -> 108.19828 | H24: =IFERROR((G24*0.6)+(F24*0.4),"") -> 110.23433
A25: 3 | C25: Gavel 3 | D25: Vara | E25: Ant | F25: Förs | G25: BV | H25: B% | I25: idx antal | J25: idx förs | K25: idx BV
B26: 101648059 | C26: g31 | D26: PK SOF SKÖLJ OUTDFR1300ML | E26: 588 | F26: 13893.44 | G26: 3069.2 | H26: =IFERROR(G26/F26,"") -> 0.22091001 | I26: =IFERROR(((E26/$B$112) / AVERAGE('V25'!E26/'V25'!$B$112, 'V26'!E26/'V26'!$B$112, 'V27'!E26/'V27'!$B$112)) * 100,"") -> 107.32294 | J26: =IFERROR(((F26/$B$112) / AVERAGE('V25'!F26/'V25'!$B$112, 'V26'!F26/'V26'!$B$112, 'V27'!F26/'V27'!$B$112)) * 100,"") -> 107.33841 | K26: =IFERROR(((G26/$B$112) / AVERAGE('V25'!G26/'V25'!$B$112, 'V26'!G26/'V26'!$B$112, 'V27'!G26/'V27'!$B$112)) * 100,"") -> 107.94154
C27: g32
C28: g33
C29: g34
C30: total | E30: =SUM(E26:E29) -> 588 | F30: =SUM(F26:F29) -> 13893.44 | G30: =SUM(G26:G29) -> 3069.2 | H30: =IFERROR(G30/F30,"") -> 0.22091001
B31: diff föreg V | E31: =IFERROR((E30-('V27'!E30))/('V27'!E30),"") -> 0.13513514 | F31: =IFERROR((F30-('V27'!F30))/('V27'!F30),"") -> 0.13535953 | G31: =IFERROR((G30-('V27'!G30))/('V27'!G30),"") -> 0.15029721 | H31: =IFERROR(H30-('V27'!H30),"") -> 0.0028687212
B32: index | E32: =E30/$B$112 -> 0.029978587 | F32: =F30/$B$112 -> 0.70834302 | G32: =G30/$B$112 -> 0.15648007
B33: index diff % | E33: =IFERROR((E32-'V27'!E32)/'V27'!E32,"") -> 0.11158053 | F33: =IFERROR((F32-'V27'!F32)/'V27'!F32,"") -> 0.11180027 | G33: =IFERROR((G32-'V27'!G32)/'V27'!G32,"") -> 0.12642798
B34: Prestations Index | E34: =(E32 / AVERAGE('V25'!E32,'V26'!E32,'V27'!E32)) * 100 -> 107.32294 | F34: =(F32 / AVERAGE('V25'!F32,'V26'!F32,'V27'!F32)) * 100 -> 107.33841 | G34: =(G32 / AVERAGE('V25'!G32,'V26'!G32,'V27'!G32)) * 100 -> 107.94154 | H34: =IFERROR((G34*0.6)+(F34*0.4),"") -> 107.70029
A35: 4 | C35: Gavel 4 | D35: Vara | E35: Ant | F35: Förs | G35: BV | H35: B% | I35: idx antal | J35: idx förs | K35: idx BV
B36: KOMBI: 101648050 101625436 | C36: g41 | D36: Softlan Appear & Van | E36: 561 | F36: 13248.88 | G36: 3016.9 | H36: =IFERROR(G36/F36,"") -> 0.22770981 | I36: =IFERROR(((E36/$B$112) / AVERAGE('V25'!E36/'V25'!$B$112, 'V26'!E36/'V26'!$B$112, 'V27'!E36/'V27'!$B$112)) * 100,"") -> 108.94285 | J36: =IFERROR(((F36/$B$112) / AVERAGE('V25'!F36/'V25'!$B$112, 'V26'!F36/'V26'!$B$112, 'V27'!F36/'V27'!$B$112)) * 100,"") -> 108.91275 | K36: =IFERROR(((G36/$B$112) / AVERAGE('V25'!G36/'V25'!$B$112, 'V26'!G36/'V26'!$B$112, 'V27'!G36/'V27'!$B$112)) * 100,"") -> 111.47656
C37: g42
C38: g43
C39: g44
C40: total | E40: =SUM(E36:E39) -> 561 | F40: =SUM(F36:F39) -> 13248.88 | G40: =SUM(G36:G39) -> 3016.9 | H40: =IFERROR(G40/F40,"") -> 0.22770981
B41: diff föreg V | E41: =IFERROR((E40-('V27'!E40))/('V27'!E40),"") -> 0.29262673 | F41: =IFERROR((F40-('V27'!F40))/('V27'!F40),"") -> 0.29241731 | G41: =IFERROR((G40-('V27'!G40))/('V27'!G40),"") -> 0.32463096 | H41: =IFERROR(H40-('V27'!H40),"") -> 0.005537667
...

Sheet V29
A1: RANKING-APP
C3: vecka 29
C4: Vecka 29 | I4: 29 | J4: mot historik
A5: 1 | C5: Gavel 1 | D5: Vara | E5: Ant | F5: Förs | G5: BV | H5: B% | I5: idx antal | J5: idx förs | K5: idx BV
B6: KOMBI: 101712096 101625435 | C6: g11 | D6: A+ Cherry blossom | E6: 99 | F6: 7124.04 | G6: 1778.04 | H6: =IFERROR(G6/F6,"") -> 0.2495831 | I6: =IFERROR(((E6/$B$112) / AVERAGE('V25'!E6/'V25'!$B$112, 'V26'!E6/'V26'!$B$112, 'V27'!E6/'V27'!$B$112, 'V28'!E6/'V28'!$B$112)) * 100,"") -> 71.151579 | J6: =IFERROR(((F6/$B$112) / AVERAGE('V25'!F6/'V25'!$B$112, 'V26'!F6/'V26'!$B$112, 'V27'!F6/'V27'!$B$112, 'V28'!F6/'V28'!$B$112)) * 100,"") -> 71.506583 | K6: =IFERROR(((G6/$B$112) / AVERAGE('V25'!G6/'V25'!$B$112, 'V26'!G6/'V26'!$B$112, 'V27'!G6/'V27'!$B$112, 'V28'!G6/'V28'!$B$112)) * 100,"") -> 77.448282
C7: g12
C8: g13
C9: g14
C10: total | E10: =SUM(E6:E9) -> 99 | F10: =SUM(F6:F9) -> 7124.04 | G10: =SUM(G6:G9) -> 1778.04 | H10: =IFERROR(G10/F10,"") -> 0.2495831
B11: diff föreg V | E11: =IFERROR((E10-('V28'!E10))/('V28'!E10),"") -> 0.90384615 | F11: =IFERROR((F10-('V28'!F10))/('V28'!F10),"") -> 0.94713998 | G11: =IFERROR((G10-('V28'!G10))/('V28'!G10),"") -> 1.4069201 | H11: =IFERROR(H10-('V28'!H10),"") -> 0.047676424
B12: index | E12: =E10/$B$112 -> 0.0045483782 | F12: =F10/$B$112 -> 0.3273013 | G12: =G10/$B$112 -> 0.081688873
B13: index diff % | E13: =IFERROR((E12-'V28'!E12)/'V28'!E12,"") -> 0.71561327 | F13: =IFERROR((F12-'V28'!F12)/'V28'!F12,"") -> 0.75462665 | G13: =IFERROR((G12-'V28'!G12)/'V28'!G12,"") -> 1.1689484
B14: Prestations Index | E14: =(E12 / AVERAGE('V25'!E12,'V26'!E12,'V27'!E12,'V28'!E12)) * 100 -> 71.151579 | F14: =(F12 / AVERAGE('V25'!F12,'V26'!F12,'V27'!F12,'V28'!F12)) * 100 -> 71.506583 | G14: =(G12 / AVERAGE('V25'!G12,'V26'!G12,'V27'!G12,'V28'!G12)) * 100 -> 77.448282 | H14: =IFERROR((G14*0.6)+(F14*0.4),"") -> 75.071602
A15: 2 | C15: Gavel 2 | D15: Vara | E15: Ant | F15: Förs | G15: BV | H15: B% | I15: idx antal | J15: idx förs | K15: idx BV
B16: KOMBI: 101595376 101595377 101595375 101547828 | C16: g21 | D16: CIF spray 750ml | E16: 215 | F16: 4288.41 | G16: 859.16 | H16: =IFERROR(G16/F16,"") -> 0.20034465 | I16: =IFERROR(((E16/$B$112) / AVERAGE('V25'!E16/'V25'!$B$112, 'V26'!E16/'V26'!$B$112, 'V27'!E16/'V27'!$B$112, 'V28'!E16/'V28'!$B$112)) * 100,"") -> 109.15077 | J16: =IFERROR(((F16/$B$112) / AVERAGE('V25'!F16/'V25'!$B$112, 'V26'!F16/'V26'!$B$112, 'V27'!F16/'V27'!$B$112, 'V28'!F16/'V28'!$B$112)) * 100,"") -> 107.84024 | K16: =IFERROR(((G16/$B$112) / AVERAGE('V25'!G16/'V25'!$B$112, 'V26'!G16/'V26'!$B$112, 'V27'!G16/'V27'!$B$112, 'V28'!G16/'V28'!$B$112)) * 100,"") -> 104.30679
C17: g22
C18: g23
C19: g24
C20: total | E20: =SUM(E16:E19) -> 215 | F20: =SUM(F16:F19) -> 4288.41 | G20: =SUM(G16:G19) -> 859.16 | H20: =IFERROR(G20/F20,"") -> 0.20034465
B21: diff föreg V | E21: =IFERROR((E20-('V28'!E20))/('V28'!E20),"") -> 0.091370558 | F21: =IFERROR((F20-('V28'!F20))/('V28'!F20),"") -> 0.091442868 | G21: =IFERROR((G20-('V28'!G20))/('V28'!G20),"") -> 0.091731578 | H21: =IFERROR(H20-('V28'!H20),"") -> 5.2981518e-05
B22: index | E22: =E20/$B$112 -> 0.0098777911 | F22: =F20/$B$112 -> 0.19702334 | G22: =G20/$B$112 -> 0.039472572
B23: index diff % | E23: =IFERROR((E22-'V28'!E22)/'V28'!E22,"") -> -0.016533027 | F23: =IFERROR((F22-'V28'!F22)/'V28'!F22,"") -> -0.016467867 | G23: =IFERROR((G22-'V28'!G22)/'V28'!G22,"") -> -0.016207701
B24: Prestations Index | E24: =(E22 / AVERAGE('V25'!E22,'V26'!E22,'V27'!E22,'V28'!E22)) * 100 -> 109.15077 | F24: =(F22 / AVERAGE('V25'!F22,'V26'!F22,'V27'!F22,'V28'!F22)) * 100 -> 107.84024 | G24: =(G22 / AVERAGE('V25'!G22,'V26'!G22,'V27'!G22,'V28'!G22)) * 100 -> 104.30679 | H24: =IFERROR((G24*0.6)+(F24*0.4),"") -> 105.72017
A25: 3 | C25: Gavel 3 | D25: Vara | E25: Ant | F25: Förs | G25: BV | H25: B% | I25: idx antal | J25: idx förs | K25: idx BV
B26: 101648059 | C26: g31 | D26: PK SOF SKÖLJ OUTDFR1300ML | E26: 797 | F26: 18827.12 | G26: 4222.4 | H26: =IFERROR(G26/F26,"") -> 0.22427222 | I26: =IFERROR(((E26/$B$112) / AVERAGE('V25'!E26/'V25'!$B$112, 'V26'!E26/'V26'!$B$112, 'V27'!E26/'V27'!$B$112, 'V28'!E26/'V28'!$B$112)) * 100,"") -> 128.73073 | J26: =IFERROR(((F26/$B$112) / AVERAGE('V25'!F26/'V25'!$B$112, 'V26'!F26/'V26'!$B$112, 'V27'!F26/'V27'!$B$112, 'V28'!F26/'V28'!$B$112)) * 100,"") -> 128.71271 | K26: =IFERROR(((G26/$B$112) / AVERAGE('V25'!G26/'V25'!$B$112, 'V26'!G26/'V26'!$B$112, 'V27'!G26/'V27'!$B$112, 'V28'!G26/'V28'!$B$112)) * 100,"") -> 131.21165
C27: g32
C28: g33
C29: g34
C30: total | E30: =SUM(E26:E29) -> 797 | F30: =SUM(F26:F29) -> 18827.12 | G30: =SUM(G26:G29) -> 4222.4 | H30: =IFERROR(G30/F30,"") -> 0.22427222
B31: diff föreg V | E31: =IFERROR((E30-('V28'!E30))/('V28'!E30),"") -> 0.35544218 | F31: =IFERROR((F30-('V28'!F30))/('V28'!F30),"") -> 0.3551086 | G31: =IFERROR((G30-('V28'!G30))/('V28'!G30),"") -> 0.37573309 | H31: =IFERROR(H30-('V28'!H30),"") -> 0.0033622079
B32: index | E32: =E30/$B$112 -> 0.036616742 | F32: =F30/$B$112 -> 0.86497841 | G32: =G30/$B$112 -> 0.19399063
B33: index diff % | E33: =IFERROR((E32-'V28'!E32)/'V28'!E32,"") -> 0.22142988 | F33: =IFERROR((F32-'V28'!F32)/'V28'!F32,"") -> 0.22112929 | G33: =IFERROR((G32-'V28'!G32)/'V28'!G32,"") -> 0.23971464
B34: Prestations Index | E34: =(E32 / AVERAGE('V25'!E32,'V26'!E32,'V27'!E32,'V28'!E32)) * 100 -> 128.73073 | F34: =(F32 / AVERAGE('V25'!F32,'V26'!F32,'V27'!F32,'V28'!F32)) * 100 -> 128.71271 | G34: =(G32 / AVERAGE('V25'!G32,'V26'!G32,'V27'!G32,'V28'!G32)) * 100 -> 131.21165 | H34: =IFERROR((G34*0.6)+(F34*0.4),"") -> 130.21208
A35: 4 | C35: Gavel 4 | D35: Vara | E35: Ant | F35: Förs | G35: BV | H35: B% | I35: idx antal | J35: idx förs | K35: idx BV
B36: KOMBI: 101648050 101625436 | C36: g41 | D36: Softlan Appear & Van | E36: 727 | F36: 17176.08 | G36: 3817.5 | H36: =IFERROR(G36/F36,"") -> 0.22225677 | I36: =IFERROR(((E36/$B$112) / AVERAGE('V25'!E36/'V25'!$B$112, 'V26'!E36/'V26'!$B$112, 'V27'!E36/'V27'!$B$112, 'V28'!E36/'V28'!$B$112)) * 100,"") -> 124.43863 | J36: =IFERROR(((F36/$B$112) / AVERAGE('V25'!F36/'V25'!$B$112, 'V26'!F36/'V26'!$B$112, 'V27'!F36/'V27'!$B$112, 'V28'!F36/'V28'!$B$112)) * 100,"") -> 124.46307 | K36: =IFERROR(((G36/$B$112) / AVERAGE('V25'!G36/'V25'!$B$112, 'V26'!G36/'V26'!$B$112, 'V27'!G36/'V27'!$B$112, 'V28'!G36/'V28'!$B$112)) * 100,"") -> 123.56746
C37: g42
C38: g43
C39: g44
C40: total | E40: =SUM(E36:E39) -> 727 | F40: =SUM(F36:F39) -> 17176.08 | G40: =SUM(G36:G39) -> 3817.5 | H40: =IFERROR(G40/F40,"") -> 0.22225677
B41: diff föreg V | E41: =IFERROR((E40-('V28'!E40))/('V28'!E40),"") -> 0.29590018 | F41: =IFERROR((F40-('V28'!F40))/('V28'!F40),"") -> 0.29641751 | G41: =IFERROR((G40-('V28'!G40))/('V28'!G40),"") -> 0.26537174 | H41: =IFERROR(H40-('V28'!H40),"") -> -0.0054530476
...

Sheet V30
A1: RANKING-APP
C3: vecka 30
C4: Vecka 30 | I4: 30 | J4: mot historik
A5: 1 | C5: Gavel 1 | D5: Vara | E5: Ant | F5: Förs | G5: BV | H5: B% | I5: idx antal | J5: idx förs | K5: idx BV
B6: KOMBI: 101712096 101625435 | C6: g11 | D6: A+ Cherry blossom | E6: 210 | F6: 15108 | G6: 3768 | H6: =IFERROR(G6/F6,"") -> 0.24940429 | I6: =IFERROR(((E6/$B$112) / AVERAGE('V25'!E6/'V25'!$B$112, 'V26'!E6/'V26'!$B$112, 'V27'!E6/'V27'!$B$112, 'V28'!E6/'V28'!$B$112, 'V29'!E6/'V29'!$B$112)) * 100,"") -> 155.08851 | J6: =IFERROR(((F6/$B$112) / AVERAGE('V25'!F6/'V25'!$B$112, 'V26'!F6/'V26'!$B$112, 'V27'!F6/'V27'!$B$112, 'V28'!F6/'V28'!$B$112, 'V29'!F6/'V29'!$B$112)) * 100,"") -> 155.70786 | K6: =IFERROR(((G6/$B$112) / AVERAGE('V25'!G6/'V25'!$B$112, 'V26'!G6/'V26'!$B$112, 'V27'!G6/'V27'!$B$112, 'V28'!G6/'V28'!$B$112, 'V29'!G6/'V29'!$B$112)) * 100,"") -> 166.42803
C7: g12
C8: g13
C9: g14
C10: total | E10: =SUM(E6:E9) -> 210 | F10: =SUM(F6:F9) -> 15108 | G10: =SUM(G6:G9) -> 3768 | H10: =IFERROR(G10/F10,"") -> 0.24940429
B11: diff föreg V | E11: =IFERROR((E10-('V29'!E10))/('V29'!E10),"") -> 1.1212121 | F11: =IFERROR((F10-('V29'!F10))/('V29'!F10),"") -> 1.1207068 | G11: =IFERROR((G10-('V29'!G10))/('V29'!G10),"") -> 1.1191874 | H11: =IFERROR(H10-('V29'!H10),"") -> -0.0001788126
B12: index | E12: =E10/$B$112 -> 0.0093420526 | F12: =F10/$B$112 -> 0.67209395 | G12: =G10/$B$112 -> 0.16762311
B13: index diff % | E13: =IFERROR((E12-'V29'!E12)/'V29'!E12,"") -> 1.0539305 | F13: =IFERROR((F12-'V29'!F12)/'V29'!F12,"") -> 1.0534412 | G13: =IFERROR((G12-'V29'!G12)/'V29'!G12,"") -> 1.05197
B14: Prestations Index | E14: =(E12 / AVERAGE('V25'!E12,'V26'!E12,'V27'!E12,'V28'!E12,'V29'!E12)) * 100 -> 155.08851 | F14: =(F12 / AVERAGE('V25'!F12,'V26'!F12,'V27'!F12,'V28'!F12,'V29'!F12)) * 100 -> 155.70786 | G14: =(G12 / AVERAGE('V25'!G12,'V26'!G12,'V27'!G12,'V28'!G12,'V29'!G12)) * 100 -> 166.42803 | H14: =IFERROR((G14*0.6)+(F14*0.4),"") -> 162.13996
A15: 2 | C15: Gavel 2 | D15: Vara | E15: Ant | F15: Förs | G15: BV | H15: B% | I15: idx antal | J15: idx förs | K15: idx BV
B16: KOMBI: 101595376 101595377 101595375 101547828 | C16: g21 | D16: CIF spray 750ml | E16: 200 | F16: 3991 | G16: 801 | H16: =IFERROR(G16/F16,"") -> 0.20070158 | I16: =IFERROR(((E16/$B$112) / AVERAGE('V25'!E16/'V25'!$B$112, 'V26'!E16/'V26'!$B$112, 'V27'!E16/'V27'!$B$112, 'V28'!E16/'V28'!$B$112, 'V29'!E16/'V29'!$B$112)) * 100,"") -> 96.548066 | J16: =IFERROR(((F16/$B$112) / AVERAGE('V25'!F16/'V25'!$B$112, 'V26'!F16/'V26'!$B$112, 'V27'!F16/'V27'!$B$112, 'V28'!F16/'V28'!$B$112, 'V29'!F16/'V29'!$B$112)) * 100,"") -> 95.677715 | K16: =IFERROR(((G16/$B$112) / AVERAGE('V25'!G16/'V25'!$B$112, 'V26'!G16/'V26'!$B$112, 'V27'!G16/'V27'!$B$112, 'V28'!G16/'V28'!$B$112, 'V29'!G16/'V29'!$B$112)) * 100,"") -> 93.357212
C17: g22
C18: g23
C19: g24
C20: total | E20: =SUM(E16:E19) -> 200 | F20: =SUM(F16:F19) -> 3991 | G20: =SUM(G16:G19) -> 801 | H20: =IFERROR(G20/F20,"") -> 0.20070158
B21: diff föreg V | E21: =IFERROR((E20-('V29'!E20))/('V29'!E20),"") -> -0.069767442 | F21: =IFERROR((F20-('V29'!F20))/('V29'!F20),"") -> -0.069352044 | G21: =IFERROR((G20-('V29'!G20))/('V29'!G20),"") -> -0.067694027 | H21: =IFERROR(H20-('V29'!H20),"") -> 0.00035692867
B22: index | E22: =E20/$B$112 -> 0.0088971929 | F22: =F20/$B$112 -> 0.17754349 | G22: =G20/$B$112 -> 0.035633258
B23: index diff % | E23: =IFERROR((E22-'V29'!E22)/'V29'!E22,"") -> -0.099273017 | F23: =IFERROR((F22-'V29'!F22)/'V29'!F22,"") -> -0.098870795 | G23: =IFERROR((G22-'V29'!G22)/'V29'!G22,"") -> -0.097265367
B24: Prestations Index | E24: =(E22 / AVERAGE('V25'!E22,'V26'!E22,'V27'!E22,'V28'!E22,'V29'!E22)) * 100 -> 96.548066 | F24: =(F22 / AVERAGE('V25'!F22,'V26'!F22,'V27'!F22,'V28'!F22,'V29'!F22)) * 100 -> 95.677715 | G24: =(G22 / AVERAGE('V25'!G22,'V26'!G22,'V27'!G22,'V28'!G22,'V29'!G22)) * 100 -> 93.357212 | H24: =IFERROR((G24*0.6)+(F24*0.4),"") -> 94.285414
A25: 3 | C25: Gavel 3 | D25: Vara | E25: Ant | F25: Förs | G25: BV | H25: B% | I25: idx antal | J25: idx förs | K25: idx BV
B26: 101648059 | C26: g31 | D26: PK SOF SKÖLJ OUTDFR1300ML | E26: 539 | F26: 12735.76 | G26: 2812 | H26: =IFERROR(G26/F26,"") -> 0.22079562 | I26: =IFERROR(((E26/$B$112) / AVERAGE('V25'!E26/'V25'!$B$112, 'V26'!E26/'V26'!$B$112, 'V27'!E26/'V27'!$B$112, 'V28'!E26/'V28'!$B$112, 'V29'!E26/'V29'!$B$112)) * 100,"") -> 79.716784 | J26: =IFERROR(((F26/$B$112) / AVERAGE('V25'!F26/'V25'!$B$112, 'V26'!F26/'V26'!$B$112, 'V27'!F26/'V27'!$B$112, 'V28'!F26/'V28'!$B$112, 'V29'!F26/'V29'!$B$112)) * 100,"") -> 79.72863 | K26: =IFERROR(((G26/$B$112) / AVERAGE('V25'!G26/'V25'!$B$112, 'V26'!G26/'V26'!$B$112, 'V27'!G26/'V27'!$B$112, 'V28'!G26/'V28'!$B$112, 'V29'!G26/'V29'!$B$112)) * 100,"") -> 79.640211
C27: g32
C28: g33
C29: g34
C30: total | E30: =SUM(E26:E29) -> 539 | F30: =SUM(F26:F29) -> 12735.76 | G30: =SUM(G26:G29) -> 2812 | H30: =IFERROR(G30/F30,"") -> 0.22079562
B31: diff föreg V | E31: =IFERROR((E30-('V29'!E30))/('V29'!E30),"") -> -0.32371393 | F31: =IFERROR((F30-('V29'!F30))/('V29'!F30),"") -> -0.32354178 | G31: =IFERROR((G30-('V29'!G30))/('V29'!G30),"") -> -0.33402804 | H31: =IFERROR(H30-('V29'!H30),"") -> -0.0034766021
B32: index | E32: =E30/$B$112 -> 0.023977935 | F32: =F30/$B$112 -> 0.56656257 | G32: =G30/$B$112 -> 0.12509453
B33: index diff % | E33: =IFERROR((E32-'V29'!E32)/'V29'!E32,"") -> -0.3451647 | F33: =IFERROR((F32-'V29'!F32)/'V29'!F32,"") -> -0.34499802 | G33: =IFERROR((G32-'V29'!G32)/'V29'!G32,"") -> -0.35515167
B34: Prestations Index | E34: =(E32 / AVERAGE('V25'!E32,'V26'!E32,'V27'!E32,'V28'!E32,'V29'!E32)) * 100 -> 79.716784 | F34: =(F32 / AVERAGE('V25'!F32,'V26'!F32,'V27'!F32,'V28'!F32,'V29'!F32)) * 100 -> 79.72863 | G34: =(G32 / AVERAGE('V25'!G32,'V26'!G32,'V27'!G32,'V28'!G32,'V29'!G32)) * 100 -> 79.640211 | H34: =IFERROR((G34*0.6)+(F34*0.4),"") -> 79.675579
A35: 4 | C35: Gavel 4 | D35: Vara | E35: Ant | F35: Förs | G35: BV | H35: B% | I35: idx antal | J35: idx förs | K35: idx BV
B36: KOMBI: 101648050 101625436 | C36: g41 | D36: Softlan Appear & Van | E36: 494 | F36: 11670.56 | G36: 2603 | H36: =IFERROR(G36/F36,"") -> 0.22303985 | I36: =IFERROR(((E36/$B$112) / AVERAGE('V25'!E36/'V25'!$B$112, 'V26'!E36/'V26'!$B$112, 'V27'!E36/'V27'!$B$112, 'V28'!E36/'V28'!$B$112, 'V29'!E36/'V29'!$B$112)) * 100,"") -> 78.059312 | J36: =IFERROR(((F36/$B$112) / AVERAGE('V25'!F36/'V25'!$B$112, 'V26'!F36/'V26'!$B$112, 'V27'!F36/'V27'!$B$112, 'V28'!F36/'V28'!$B$112, 'V29'!F36/'V29'!$B$112)) * 100,"") -> 78.066528 | K36: =IFERROR(((G36/$B$112) / AVERAGE('V25'!G36/'V25'!$B$112, 'V26'!G36/'V26'!$B$112, 'V27'!G36/'V27'!$B$112, 'V28'!G36/'V28'!$B$112, 'V29'!G36/'V29'!$B$112)) * 100,"") -> 77.910904
C37: g42
C38: g43
C39: g44
C40: total | E40: =SUM(E36:E39) -> 494 | F40: =SUM(F36:F39) -> 11670.56 | G40: =SUM(G36:G39) -> 2603 | H40: =IFERROR(G40/F40,"") -> 0.22303985
B41: diff föreg V | E41: =IFERROR((E40-('V29'!E40))/('V29'!E40),"") -> -0.32049519 | F41: =IFERROR((F40-('V29'!F40))/('V29'!F40),"") -> -0.32053414 | G41: =IFERROR((G40-('V29'!G40))/('V29'!G40),"") -> -0.31814014 | H41: =IFERROR(H40-('V29'!H40),"") -> 0.00078308774
...

Sheet V31
A1: RANKING-APP
C3: vecka 31
C4: Vecka 31 | I4: 31 | J4: mot historik
A5: 1 | C5: Gavel 1 | D5: Vara | E5: Ant | F5: Förs | G5: BV | H5: B% | I5: idx antal | J5: idx förs | K5: idx BV
B6: KOMBI: 101712096 101625435 | C6: g11 | D6: A+ Cherry blossom | E6: 199 | F6: 14320.04 | G6: 3574.04 | H6: =IFERROR(G6/F6,"") -> 0.2495831 | I6: =IFERROR(((E6/$B$112) / AVERAGE('V25'!E6/'V25'!$B$112, 'V26'!E6/'V26'!$B$112, 'V27'!E6/'V27'!$B$112, 'V28'!E6/'V28'!$B$112, 'V29'!E6/'V29'!$B$112, 'V30'!E6/'V30'!$B$112)) * 100,"") -> 141.92355 | J6: =IFERROR(((F6/$B$112) / AVERAGE('V25'!F6/'V25'!$B$112, 'V26'!F6/'V26'!$B$112, 'V27'!F6/'V27'!$B$112, 'V28'!F6/'V28'!$B$112, 'V29'!F6/'V29'!$B$112, 'V30'!F6/'V30'!$B$112)) * 100,"") -> 142.38965 | K6: =IFERROR(((G6/$B$112) / AVERAGE('V25'!G6/'V25'!$B$112, 'V26'!G6/'V26'!$B$112, 'V27'!G6/'V27'!$B$112, 'V28'!G6/'V28'!$B$112, 'V29'!G6/'V29'!$B$112, 'V30'!G6/'V30'!$B$112)) * 100,"") -> 149.85207
C7: g12
C8: g13
C9: g14
C10: total | E10: =SUM(E6:E9) -> 199 | F10: =SUM(F6:F9) -> 14320.04 | G10: =SUM(G6:G9) -> 3574.04 | H10: =IFERROR(G10/F10,"") -> 0.2495831
B11: diff föreg V | E11: =IFERROR((E10-('V30'!E10))/('V30'!E10),"") -> -0.052380952 | F11: =IFERROR((F10-('V30'!F10))/('V30'!F10),"") -> -0.05215515 | G11: =IFERROR((G10-('V30'!G10))/('V30'!G10),"") -> -0.051475584 | H11: =IFERROR(H10-('V30'!H10),"") -> 0.0001788126
B12: index | E12: =E10/$B$112 -> 0.0093339587 | F12: =F10/$B$112 -> 0.67167167 | G12: =G10/$B$112 -> 0.1676379
B13: index diff % | E13: =IFERROR((E12-'V30'!E12)/'V30'!E12,"") -> -0.00086638971 | F13: =IFERROR((F12-'V30'!F12)/'V30'!F12,"") -> -0.0006283118 | G13: =IFERROR((G12-'V30'!G12)/'V30'!G12,"") -> 8.8196544e-05
B14: Prestations Index | E14: =(E12 / AVERAGE('V25'!E12,'V26'!E12,'V27'!E12,'V28'!E12,'V29'!E12,'V30'!E12)) * 100 -> 141.92355 | F14: =(F12 / AVERAGE('V25'!F12,'V26'!F12,'V27'!F12,'V28'!F12,'V29'!F12,'V30'!F12)) * 100 -> 142.38965 | G14: =(G12 / AVERAGE('V25'!G12,'V26'!G12,'V27'!G12,'V28'!G12,'V29'!G12,'V30'!G12)) * 100 -> 149.85207 | H14: =IFERROR((G14*0.6)+(F14*0.4),"") -> 146.86711
A15: 2 | C15: Gavel 2 | D15: Vara | E15: Ant | F15: Förs | G15: BV | H15: B% | I15: idx antal | J15: idx förs | K15: idx BV
B16: KOMBI: 101595376 101595377 101595375 101547828 | C16: g21 | D16: CIF spray 750ml | E16: 158 | F16: 3153.68 | G16: 601.68 | H16: =IFERROR(G16/F16,"") -> 0.19078664 | I16: =IFERROR(((E16/$B$112) / AVERAGE('V25'!E16/'V25'!$B$112, 'V26'!E16/'V26'!$B$112, 'V27'!E16/'V27'!$B$112, 'V28'!E16/'V28'!$B$112, 'V29'!E16/'V29'!$B$112, 'V30'!E16/'V30'!$B$112)) * 100,"") -> 80.884679 | J16: =IFERROR(((F16/$B$112) / AVERAGE('V25'!F16/'V25'!$B$112, 'V26'!F16/'V26'!$B$112, 'V27'!F16/'V27'!$B$112, 'V28'!F16/'V28'!$B$112, 'V29'!F16/'V29'!$B$112, 'V30'!F16/'V30'!$B$112)) * 100,"") -> 80.292758 | K16: =IFERROR(((G16/$B$112) / AVERAGE('V25'!G16/'V25'!$B$112, 'V26'!G16/'V26'!$B$112, 'V27'!G16/'V27'!$B$112, 'V28'!G16/'V28'!$B$112, 'V29'!G16/'V29'!$B$112, 'V30'!G16/'V30'!$B$112)) * 100,"") -> 74.766275
C17: g22
C18: g23
C19: g24
C20: total | E20: =SUM(E16:E19) -> 158 | F20: =SUM(F16:F19) -> 3153.68 | G20: =SUM(G16:G19) -> 601.68 | H20: =IFERROR(G20/F20,"") -> 0.19078664
B21: diff föreg V | E21: =IFERROR((E20-('V30'!E20))/('V30'!E20),"") -> -0.21 | F21: =IFERROR((F20-('V30'!F20))/('V30'!F20),"") -> -0.20980205 | G21: =IFERROR((G20-('V30'!G20))/('V30'!G20),"") -> -0.24883895 | H21: =IFERROR(H20-('V30'!H20),"") -> -0.009914942
B22: index | E22: =E20/$B$112 -> 0.0074108818 | F22: =F20/$B$112 -> 0.1479212 | G22: =G20/$B$112 -> 0.028221388
B23: index diff % | E23: =IFERROR((E22-'V30'!E22)/'V30'!E22,"") -> -0.16705394 | F23: =IFERROR((F22-'V30'!F22)/'V30'!F22,"") -> -0.16684523 | G23: =IFERROR((G22-'V30'!G22)/'V30'!G22,"") -> -0.20800426
B24: Prestations Index | E24: =(E22 / AVERAGE('V25'!E22,'V26'!E22,'V27'!E22,'V28'!E22,'V29'!E22,'V30'!E22)) * 100 -> 80.884679 | F24: =(F22 / AVERAGE('V25'!F22,'V26'!F22,'V27'!F22,'V28'!F22,'V29'!F22,'V30'!F22)) * 100 -> 80.292758 | G24: =(G22 / AVERAGE('V25'!G22,'V26'!G22,'V27'!G22,'V28'!G22,'V29'!G22,'V30'!G22)) * 100 -> 74.766275 | H24: =IFERROR((G24*0.6)+(F24*0.4),"") -> 76.976869
A25: 3 | C25: Gavel 3 | D25: Vara | E25: Ant | F25: Förs | G25: BV | H25: B% | I25: idx antal | J25: idx förs | K25: idx BV
B26: 101648059 | C26: g31 | D26: PK SOF SKÖLJ OUTDFR1300ML | E26: 712 | F26: 16817.56 | G26: 3742.84 | H26: =IFERROR(G26/F26,"") -> 0.22255547 | I26: =IFERROR(((E26/$B$112) / AVERAGE('V25'!E26/'V25'!$B$112, 'V26'!E26/'V26'!$B$112, 'V27'!E26/'V27'!$B$112, 'V28'!E26/'V28'!$B$112, 'V29'!E26/'V29'!$B$112, 'V30'!E26/'V30'!$B$112)) * 100,"") -> 114.91221 | J26: =IFERROR(((F26/$B$112) / AVERAGE('V25'!F26/'V25'!$B$112, 'V26'!F26/'V26'!$B$112, 'V27'!F26/'V27'!$B$112, 'V28'!F26/'V28'!$B$112, 'V29'!F26/'V29'!$B$112, 'V30'!F26/'V30'!$B$112)) * 100,"") -> 114.88642 | K26: =IFERROR(((G26/$B$112) / AVERAGE('V25'!G26/'V25'!$B$112, 'V26'!G26/'V26'!$B$112, 'V27'!G26/'V27'!$B$112, 'V28'!G26/'V28'!$B$112, 'V29'!G26/'V29'!$B$112, 'V30'!G26/'V30'!$B$112)) * 100,"") -> 115.69135
C27: g32
C28: g33
C29: g34
C30: total | E30: =SUM(E26:E29) -> 712 | F30: =SUM(F26:F29) -> 16817.56 | G30: =SUM(G26:G29) -> 3742.84 | H30: =IFERROR(G30/F30,"") -> 0.22255547
B31: diff föreg V | E31: =IFERROR((E30-('V30'!E30))/('V30'!E30),"") -> 0.32096475 | F31: =IFERROR((F30-('V30'!F30))/('V30'!F30),"") -> 0.32049913 | G31: =IFERROR((G30-('V30'!G30))/('V30'!G30),"") -> 0.33102418 | H31: =IFERROR(H30-('V30'!H30),"") -> 0.0017598538
B32: index | E32: =E30/$B$112 -> 0.033395872 | F32: =F30/$B$112 -> 0.78881614 | G32: =G30/$B$112 -> 0.17555535
B33: index diff % | E33: =IFERROR((E32-'V30'!E32)/'V30'!E32,"") -> 0.39277517 | F33: =IFERROR((F32-'V30'!F32)/'V30'!F32,"") -> 0.39228424 | G33: =IFERROR((G32-'V30'!G32)/'V30'!G32,"") -> 0.40338145
B34: Prestations Index | E34: =(E32 / AVERAGE('V25'!E32,'V26'!E32,'V27'!E32,'V28'!E32,'V29'!E32,'V30'!E32)) * 100 -> 114.91221 | F34: =(F32 / AVERAGE('V25'!F32,'V26'!F32,'V27'!F32,'V28'!F32,'V29'!F32,'V30'!F32)) * 100 -> 114.88642 | G34: =(G32 / AVERAGE('V25'!G32,'V26'!G32,'V27'!G32,'V28'!G32,'V29'!G32,'V30'!G32)) * 100 -> 115.69135 | H34: =IFERROR((G34*0.6)+(F34*0.4),"") -> 115.36938
A35: 4 | C35: Gavel 4 | D35: Vara | E35: Ant | F35: Förs | G35: BV | H35: B% | I35: idx antal | J35: idx förs | K35: idx BV
B36: KOMBI: 101648050 101625436 | C36: g41 | D36: Softlan Appear & Van | E36: 498 | F36: 11762.28 | G36: 2627.34 | H36: =IFERROR(G36/F36,"") -> 0.22336996 | I36: =IFERROR(((E36/$B$112) / AVERAGE('V25'!E36/'V25'!$B$112, 'V26'!E36/'V26'!$B$112, 'V27'!E36/'V27'!$B$112, 'V28'!E36/'V28'!$B$112, 'V29'!E36/'V29'!$B$112, 'V30'!E36/'V30'!$B$112)) * 100,"") -> 86.118359 | J36: =IFERROR(((F36/$B$112) / AVERAGE('V25'!F36/'V25'!$B$112, 'V26'!F36/'V26'!$B$112, 'V27'!F36/'V27'!$B$112, 'V28'!F36/'V28'!$B$112, 'V29'!F36/'V29'!$B$112, 'V30'!F36/'V30'!$B$112)) * 100,"") -> 86.104906 | K36: =IFERROR(((G36/$B$112) / AVERAGE('V25'!G36/'V25'!$B$112, 'V26'!G36/'V26'!$B$112, 'V27'!G36/'V27'!$B$112, 'V28'!G36/'V28'!$B$112, 'V29'!G36/'V29'!$B$112, 'V30'!G36/'V30'!$B$112)) * 100,"") -> 86.083616
C37: g42
C38: g43
C39: g44
C40: total | E40: =SUM(E36:E39) -> 498 | F40: =SUM(F36:F39) -> 11762.28 | G40: =SUM(G36:G39) -> 2627.34 | H40: =IFERROR(G40/F40,"") -> 0.22336996
B41: diff föreg V | E41: =IFERROR((E40-('V30'!E40))/('V30'!E40),"") -> 0.008097166 | F41: =IFERROR((F40-('V30'!F40))/('V30'!F40),"") -> 0.0078590916 | G41: =IFERROR((G40-('V30'!G40))/('V30'!G40),"") -> 0.0093507491 | H41: =IFERROR(H40-('V30'!H40),"") -> 0.00033010476
...

Sheet V32
A1: RANKING-APP
C3: vecka 32
C4: Vecka 32 | I4: 32 | J4: mot historik
A5: 1 | C5: Gavel 1 | D5: Vara | E5: Ant | F5: Förs | G5: BV | H5: B% | I5: idx antal | J5: idx förs | K5: idx BV
B6: KOMBI: 101712096 101625435 | C6: g11 | D6: A+ Cherry blossom | E6: 174 | F6: 12517.44 | G6: 3121.44 | H6: =IFERROR(G6/F6,"") -> 0.24936728 | I6: =IFERROR(((E6/$B$112) / AVERAGE('V25'!E6/'V25'!$B$112, 'V26'!E6/'V26'!$B$112, 'V27'!E6/'V27'!$B$112, 'V28'!E6/'V28'!$B$112, 'V29'!E6/'V29'!$B$112, 'V30'!E6/'V30'!$B$112, 'V31'!E6/'V31'!$B$112)) * 100,"") -> 133.57868 | J6: =IFERROR(((F6/$B$112) / AVERAGE('V25'!F6/'V25'!$B$112, 'V26'!F6/'V26'!$B$112, 'V27'!F6/'V27'!$B$112, 'V28'!F6/'V28'!$B$112, 'V29'!F6/'V29'!$B$112, 'V30'!F6/'V30'!$B$112, 'V31'!F6/'V31'!$B$112)) * 100,"") -> 133.89472 | K6: =IFERROR(((G6/$B$112) / AVERAGE('V25'!G6/'V25'!$B$112, 'V26'!G6/'V26'!$B$112, 'V27'!G6/'V27'!$B$112, 'V28'!G6/'V28'!$B$112, 'V29'!G6/'V29'!$B$112, 'V30'!G6/'V30'!$B$112, 'V31'!G6/'V31'!$B$112)) * 100,"") -> 139.38897
C7: g12
C8: g13
C9: g14
C10: total | E10: =SUM(E6:E9) -> 174 | F10: =SUM(F6:F9) -> 12517.44 | G10: =SUM(G6:G9) -> 3121.44 | H10: =IFERROR(G10/F10,"") -> 0.24936728
B11: diff föreg V | E11: =IFERROR((E10-('V31'!E10))/('V31'!E10),"") -> -0.12562814 | F11: =IFERROR((F10-('V31'!F10))/('V31'!F10),"") -> -0.12587954 | G11: =IFERROR((G10-('V31'!G10))/('V31'!G10),"") -> -0.1266354 | H11: =IFERROR(H10-('V31'!H10),"") -> -0.00021581896
B12: index | E12: =E10/$B$112 -> 0.0093112859 | F12: =F10/$B$112 -> 0.66984749 | G12: =G10/$B$112 -> 0.16703805
B13: index diff % | E13: =IFERROR((E12-'V31'!E12)/'V31'!E12,"") -> -0.0024290662 | F13: =IFERROR((F12-'V31'!F12)/'V31'!F12,"") -> -0.0027158838 | G13: =IFERROR((G12-'V31'!G12)/'V31'!G12,"") -> -0.0035782532
B14: Prestations Index | E14: =(E12 / AVERAGE('V25'!E12,'V26'!E12,'V27'!E12,'V28'!E12,'V29'!E12,'V30'!E12,'V31'!E12)) * 100 -> 133.57868 | F14: =(F12 / AVERAGE('V25'!F12,'V26'!F12,'V27'!F12,'V28'!F12,'V29'!F12,'V30'!F12,'V31'!F12)) * 100 -> 133.89472 | G14: =(G12 / AVERAGE('V25'!G12,'V26'!G12,'V27'!G12,'V28'!G12,'V29'!G12,'V30'!G12,'V31'!G12)) * 100 -> 139.38897 | H14: =IFERROR((G14*0.6)+(F14*0.4),"") -> 137.19127
A15: 2 | C15: Gavel 2 | D15: Vara | E15: Ant | F15: Förs | G15: BV | H15: B% | I15: idx antal | J15: idx förs | K15: idx BV
B16: KOMBI: 101595376 101595377 101595375 101547828 | C16: g21 | D16: CIF spray 750ml | E16: 170 | F16: 3393.2 | G16: 681.7 | H16: =IFERROR(G16/F16,"") -> 0.2009018 | I16: =IFERROR(((E16/$B$112) / AVERAGE('V25'!E16/'V25'!$B$112, 'V26'!E16/'V26'!$B$112, 'V27'!E16/'V27'!$B$112, 'V28'!E16/'V28'!$B$112, 'V29'!E16/'V29'!$B$112, 'V30'!E16/'V30'!$B$112, 'V31'!E16/'V31'!$B$112)) * 100,"") -> 102.07754 | J16: =IFERROR(((F16/$B$112) / AVERAGE('V25'!F16/'V25'!$B$112, 'V26'!F16/'V26'!$B$112, 'V27'!F16/'V27'!$B$112, 'V28'!F16/'V28'!$B$112, 'V29'!F16/'V29'!$B$112, 'V30'!F16/'V30'!$B$112, 'V31'!F16/'V31'!$B$112)) * 100,"") -> 101.4187 | K16: =IFERROR(((G16/$B$112) / AVERAGE('V25'!G16/'V25'!$B$112, 'V26'!G16/'V26'!$B$112, 'V27'!G16/'V27'!$B$112, 'V28'!G16/'V28'!$B$112, 'V29'!G16/'V29'!$B$112, 'V30'!G16/'V30'!$B$112, 'V31'!G16/'V31'!$B$112)) * 100,"") -> 100.25955
C17: g22
C18: g23
C19: g24
C20: total | E20: =SUM(E16:E19) -> 170 | F20: =SUM(F16:F19) -> 3393.2 | G20: =SUM(G16:G19) -> 681.7 | H20: =IFERROR(G20/F20,"") -> 0.2009018
B21: diff föreg V | E21: =IFERROR((E20-('V31'!E20))/('V31'!E20),"") -> 0.075949367 | F21: =IFERROR((F20-('V31'!F20))/('V31'!F20),"") -> 0.075949367 | G21: =IFERROR((G20-('V31'!G20))/('V31'!G20),"") -> 0.13299428 | H21: =IFERROR(H20-('V31'!H20),"") -> 0.010115167
B22: index | E22: =E20/$B$112 -> 0.0090972334 | F22: =F20/$B$112 -> 0.18158078 | G22: =G20/$B$112 -> 0.036479906
B23: index diff % | E23: =IFERROR((E22-'V31'!E22)/'V31'!E22,"") -> 0.22755073 | F23: =IFERROR((F22-'V31'!F22)/'V31'!F22,"") -> 0.22755073 | G23: =IFERROR((G22-'V31'!G22)/'V31'!G22,"") -> 0.29263328
B24: Prestations Index | E24: =(E22 / AVERAGE('V25'!E22,'V26'!E22,'V27'!E22,'V28'!E22,'V29'!E22,'V30'!E22,'V31'!E22)) * 100 -> 102.07754 | F24: =(F22 / AVERAGE('V25'!F22,'V26'!F22,'V27'!F22,'V28'!F22,'V29'!F22,'V30'!F22,'V31'!F22)) * 100 -> 101.4187 | G24: =(G22 / AVERAGE('V25'!G22,'V26'!G22,'V27'!G22,'V28'!G22,'V29'!G22,'V30'!G22,'V31'!G22)) * 100 -> 100.25955 | H24: =IFERROR((G24*0.6)+(F24*0.4),"") -> 100.72321
A25: 3 | C25: Gavel 3 | D25: Vara | E25: Ant | F25: Förs | G25: BV | H25: B% | I25: idx antal | J25: idx förs | K25: idx BV
B26: 101648059 | C26: g31 | D26: PK SOF SKÖLJ OUTDFR1300ML | E26: 604 | F26: 14274.76 | G26: 3074.74 | H26: =IFERROR(G26/F26,"") -> 0.21539697 | I26: =IFERROR(((E26/$B$112) / AVERAGE('V25'!E26/'V25'!$B$112, 'V26'!E26/'V26'!$B$112, 'V27'!E26/'V27'!$B$112, 'V28'!E26/'V28'!$B$112, 'V29'!E26/'V29'!$B$112, 'V30'!E26/'V30'!$B$112, 'V31'!E26/'V31'!$B$112)) * 100,"") -> 108.89703 | J26: =IFERROR(((F26/$B$112) / AVERAGE('V25'!F26/'V25'!$B$112, 'V26'!F26/'V26'!$B$112, 'V27'!F26/'V27'!$B$112, 'V28'!F26/'V28'!$B$112, 'V29'!F26/'V29'!$B$112, 'V30'!F26/'V30'!$B$112, 'V31'!F26/'V31'!$B$112)) * 100,"") -> 108.93894 | K26: =IFERROR(((G26/$B$112) / AVERAGE('V25'!G26/'V25'!$B$112, 'V26'!G26/'V26'!$B$112, 'V27'!G26/'V27'!$B$112, 'V28'!G26/'V28'!$B$112, 'V29'!G26/'V29'!$B$112, 'V30'!G26/'V30'!$B$112, 'V31'!G26/'V31'!$B$112)) * 100,"") -> 106.05421
C27: g32
C28: g33
C29: g34
C30: total | E30: =SUM(E26:E29) -> 604 | F30: =SUM(F26:F29) -> 14274.76 | G30: =SUM(G26:G29) -> 3074.74 | H30: =IFERROR(G30/F30,"") -> 0.21539697
B31: diff föreg V | E31: =IFERROR((E30-('V31'!E30))/('V31'!E30),"") -> -0.15168539 | F31: =IFERROR((F30-('V31'!F30))/('V31'!F30),"") -> -0.1511991 | G31: =IFERROR((G30-('V31'!G30))/('V31'!G30),"") -> -0.17850082 | H31: =IFERROR(H30-('V31'!H30),"") -> -0.0071585054
B32: index | E32: =E30/$B$112 -> 0.032321935 | F32: =F30/$B$112 -> 0.76388719 | G32: =G30/$B$112 -> 0.16453898
B33: index diff % | E33: =IFERROR((E32-'V31'!E32)/'V31'!E32,"") -> -0.032157788 | F33: =IFERROR((F32-'V31'!F32)/'V31'!F32,"") -> -0.03160298 | G33: =IFERROR((G32-'V31'!G32)/'V31'!G32,"") -> -0.062751508
B34: Prestations Index | E34: =(E32 / AVERAGE('V25'!E32,'V26'!E32,'V27'!E32,'V28'!E32,'V29'!E32,'V30'!E32,'V31'!E32)) * 100 -> 108.89703 | F34: =(F32 / AVERAGE('V25'!F32,'V26'!F32,'V27'!F32,'V28'!F32,'V29'!F32,'V30'!F32,'V31'!F32)) * 100 -> 108.93894 | G34: =(G32 / AVERAGE('V25'!G32,'V26'!G32,'V27'!G32,'V28'!G32,'V29'!G32,'V30'!G32,'V31'!G32)) * 100 -> 106.05421 | H34: =IFERROR((G34*0.6)+(F34*0.4),"") -> 107.2081
A35: 4 | C35: Gavel 4 | D35: Vara | E35: Ant | F35: Förs | G35: BV | H35: B% | I35: idx antal | J35: idx förs | K35: idx BV
B36: KOMBI: 101648050 101625436 | C36: g41 | D36: Softlan Appear & Van | E36: 458 | F36: 10820 | G36: 2414.3 | H36: =IFERROR(G36/F36,"") -> 0.22313309 | I36: =IFERROR(((E36/$B$112) / AVERAGE('V25'!E36/'V25'!$B$112, 'V26'!E36/'V26'!$B$112, 'V27'!E36/'V27'!$B$112, 'V28'!E36/'V28'!$B$112, 'V29'!E36/'V29'!$B$112, 'V30'!E36/'V30'!$B$112, 'V31'!E36/'V31'!$B$112)) * 100,"") -> 92.188871 | J36: =IFERROR(((F36/$B$112) / AVERAGE('V25'!F36/'V25'!$B$112, 'V26'!F36/'V26'!$B$112, 'V27'!F36/'V27'!$B$112, 'V28'!F36/'V28'!$B$112, 'V29'!F36/'V29'!$B$112, 'V30'!F36/'V30'!$B$112, 'V31'!F36/'V31'!$B$112)) * 100,"") -> 92.197422 | K36: =IFERROR(((G36/$B$112) / AVERAGE('V25'!G36/'V25'!$B$112, 'V26'!G36/'V26'!$B$112, 'V27'!G36/'V27'!$B$112, 'V28'!G36/'V28'!$B$112, 'V29'!G36/'V29'!$B$112, 'V30'!G36/'V30'!$B$112, 'V31'!G36/'V31'!$B$112)) * 100,"") -> 92.079736
C37: g42
C38: g43
C39: g44
C40: total | E40: =SUM(E36:E39) -> 458 | F40: =SUM(F36:F39) -> 10820 | G40: =SUM(G36:G39) -> 2414.3 | H40: =IFERROR(G40/F40,"") -> 0.22313309
B41: diff föreg V | E41: =IFERROR((E40-('V31'!E40))/('V31'!E40),"") -> -0.080321285 | F41: =IFERROR((F40-('V31'!F40))/('V31'!F40),"") -> -0.080110319 | G41: =IFERROR((G40-('V31'!G40))/('V31'!G40),"") -> -0.081085813 | H41: =IFERROR(H40-('V31'!H40),"") -> -0.00023687201
...

Sheet V33
A1: RANKING-APP
C3: vecka 33
C4: Vecka 33 | I4: 33 | J4: mot historik
A5: 1 | C5: Gavel 1 | D5: Vara | E5: Ant | F5: Förs | G5: BV | H5: B% | I5: idx antal | J5: idx förs | K5: idx BV
B6: KOMBI: 101712096 101625435 | C6: g11 | D6: A+ Cherry blossom | E6: 163 | F6: 11722.28 | G6: 976.78 | H6: =IFERROR(G6/F6,"") -> 0.083326793 | I6: =IFERROR(((E6/$B$112) / AVERAGE('V25'!E6/'V25'!$B$112, 'V26'!E6/'V26'!$B$112, 'V27'!E6/'V27'!$B$112, 'V28'!E6/'V28'!$B$112, 'V29'!E6/'V29'!$B$112, 'V30'!E6/'V30'!$B$112, 'V31'!E6/'V31'!$B$112, 'V32'!E6/'V32'!$B$112)) * 100,"") -> 121.19588 | J6: =IFERROR(((F6/$B$112) / AVERAGE('V25'!F6/'V25'!$B$112, 'V26'!F6/'V26'!$B$112, 'V27'!F6/'V27'!$B$112, 'V28'!F6/'V28'!$B$112, 'V29'!F6/'V29'!$B$112, 'V30'!F6/'V30'!$B$112, 'V31'!F6/'V31'!$B$112, 'V32'!F6/'V32'!$B$112)) * 100,"") -> 121.39695 | K6: =IFERROR(((G6/$B$112) / AVERAGE('V25'!G6/'V25'!$B$112, 'V26'!G6/'V26'!$B$112, 'V27'!G6/'V27'!$B$112, 'V28'!G6/'V28'!$B$112, 'V29'!G6/'V29'!$B$112, 'V30'!G6/'V30'!$B$112, 'V31'!G6/'V31'!$B$112, 'V32'!G6/'V32'!$B$112)) * 100,"") -> 41.953274
C7: g12
C8: g13
C9: g14
C10: total | E10: =SUM(E6:E9) -> 163 | F10: =SUM(F6:F9) -> 11722.28 | G10: =SUM(G6:G9) -> 976.78 | H10: =IFERROR(G10/F10,"") -> 0.083326793
B11: diff föreg V | E11: =IFERROR((E10-('V32'!E10))/('V32'!E10),"") -> -0.063218391 | F11: =IFERROR((F10-('V32'!F10))/('V32'!F10),"") -> -0.063524171 | G11: =IFERROR((G10-('V32'!G10))/('V32'!G10),"") -> -0.68707391 | H11: =IFERROR(H10-('V32'!H10),"") -> -0.16604049
B12: index | E12: =E10/$B$112 -> 0.0088027218 | F12: =F10/$B$112 -> 0.63305503 | G12: =G10/$B$112 -> 0.052750446
B13: index diff % | E13: =IFERROR((E12-'V32'!E12)/'V32'!E12,"") -> -0.05461803 | F13: =IFERROR((F12-'V32'!F12)/'V32'!F12,"") -> -0.054926618 | G13: =IFERROR((G12-'V32'!G12)/'V32'!G12,"") -> -0.68420102
B14: Prestations Index | E14: =(E12 / AVERAGE('V25'!E12,'V26'!E12,'V27'!E12,'V28'!E12,'V29'!E12,'V30'!E12,'V31'!E12,'V32'!E12)) * 100 -> 121.19588 | F14: =(F12 / AVERAGE('V25'!F12,'V26'!F12,'V27'!F12,'V28'!F12,'V29'!F12,'V30'!F12,'V31'!F12,'V32'!F12)) * 100 -> 121.39695 | G14: =(G12 / AVERAGE('V25'!G12,'V26'!G12,'V27'!G12,'V28'!G12,'V29'!G12,'V30'!G12,'V31'!G12,'V32'!G12)) * 100 -> 41.953274 | H14: =IFERROR((G14*0.6)+(F14*0.4),"") -> 73.730742
A15: 2 | C15: Gavel 2 | D15: Vara | E15: Ant | F15: Förs | G15: BV | H15: B% | I15: idx antal | J15: idx förs | K15: idx BV
B16: KOMBI: 101595376 101595377 101595375 101547828 | C16: g21 | D16: CIF spray 750ml | E16: 198 | F16: 3200.08 | G16: 417.98 | H16: =IFERROR(G16/F16,"") -> 0.13061548 | I16: =IFERROR(((E16/$B$112) / AVERAGE('V25'!E16/'V25'!$B$112, 'V26'!E16/'V26'!$B$112, 'V27'!E16/'V27'!$B$112, 'V28'!E16/'V28'!$B$112, 'V29'!E16/'V29'!$B$112, 'V30'!E16/'V30'!$B$112, 'V31'!E16/'V31'!$B$112, 'V32'!E16/'V32'!$B$112)) * 100,"") -> 119.67104 | J16: =IFERROR(((F16/$B$112) / AVERAGE('V25'!F16/'V25'!$B$112, 'V26'!F16/'V26'!$B$112, 'V27'!F16/'V27'!$B$112, 'V28'!F16/'V28'!$B$112, 'V29'!F16/'V29'!$B$112, 'V30'!F16/'V30'!$B$112, 'V31'!F16/'V31'!$B$112, 'V32'!F16/'V32'!$B$112)) * 100,"") -> 96.353806 | K16: =IFERROR(((G16/$B$112) / AVERAGE('V25'!G16/'V25'!$B$112, 'V26'!G16/'V26'!$B$112, 'V27'!G16/'V27'!$B$112, 'V28'!G16/'V28'!$B$112, 'V29'!G16/'V29'!$B$112, 'V30'!G16/'V30'!$B$112, 'V31'!G16/'V31'!$B$112, 'V32'!G16/'V32'!$B$112)) * 100,"") -> 62.017755
C17: g22
C18: g23
C19: g24
C20: total | E20: =SUM(E16:E19) -> 198 | F20: =SUM(F16:F19) -> 3200.08 | G20: =SUM(G16:G19) -> 417.98 | H20: =IFERROR(G20/F20,"") -> 0.13061548
B21: diff föreg V | E21: =IFERROR((E20-('V32'!E20))/('V32'!E20),"") -> 0.16470588 | F21: =IFERROR((F20-('V32'!F20))/('V32'!F20),"") -> -0.056913828 | G21: =IFERROR((G20-('V32'!G20))/('V32'!G20),"") -> -0.38685639 | H21: =IFERROR(H20-('V32'!H20),"") -> -0.070286319
B22: index | E22: =E20/$B$112 -> 0.010692877 | F22: =F20/$B$112 -> 0.17281849 | G22: =G20/$B$112 -> 0.022572771
B23: index diff % | E23: =IFERROR((E22-'V32'!E22)/'V32'!E22,"") -> 0.17539876 | F23: =IFERROR((F22-'V32'!F22)/'V32'!F22,"") -> -0.048255587 | G23: =IFERROR((G22-'V32'!G22)/'V32'!G22,"") -> -0.38122727
B24: Prestations Index | E24: =(E22 / AVERAGE('V25'!E22,'V26'!E22,'V27'!E22,'V28'!E22,'V29'!E22,'V30'!E22,'V31'!E22,'V32'!E22)) * 100 -> 119.67104 | F24: =(F22 / AVERAGE('V25'!F22,'V26'!F22,'V27'!F22,'V28'!F22,'V29'!F22,'V30'!F22,'V31'!F22,'V32'!F22)) * 100 -> 96.353806 | G24: =(G22 / AVERAGE('V25'!G22,'V26'!G22,'V27'!G22,'V28'!G22,'V29'!G22,'V30'!G22,'V31'!G22,'V32'!G22)) * 100 -> 62.017755 | H24: =IFERROR((G24*0.6)+(F24*0.4),"") -> 75.752175
A25: 3 | C25: Gavel 3 | D25: Vara | E25: Ant | F25: Förs | G25: BV | H25: B% | I25: idx antal | J25: idx förs | K25: idx BV
B26: 101648059 | C26: g31 | D26: PK SOF SKÖLJ OUTDFR1300ML | E26: 679 | F26: 16045.84 | G26: 3514.3 | H26: =IFERROR(G26/F26,"") -> 0.21901627 | I26: =IFERROR(((E26/$B$112) / AVERAGE('V25'!E26/'V25'!$B$112, 'V26'!E26/'V26'!$B$112, 'V27'!E26/'V27'!$B$112, 'V28'!E26/'V28'!$B$112, 'V29'!E26/'V29'!$B$112, 'V30'!E26/'V30'!$B$112, 'V31'!E26/'V31'!$B$112, 'V32'!E26/'V32'!$B$112)) * 100,"") -> 122.18407 | J26: =IFERROR(((F26/$B$112) / AVERAGE('V25'!F26/'V25'!$B$112, 'V26'!F26/'V26'!$B$112, 'V27'!F26/'V27'!$B$112, 'V28'!F26/'V28'!$B$112, 'V29'!F26/'V29'!$B$112, 'V30'!F26/'V30'!$B$112, 'V31'!F26/'V31'!$B$112, 'V32'!F26/'V32'!$B$112)) * 100,"") -> 122.21373 | K26: =IFERROR(((G26/$B$112) / AVERAGE('V25'!G26/'V25'!$B$112, 'V26'!G26/'V26'!$B$112, 'V27'!G26/'V27'!$B$112, 'V28'!G26/'V28'!$B$112, 'V29'!G26/'V29'!$B$112, 'V30'!G26/'V30'!$B$112, 'V31'!G26/'V31'!$B$112, 'V32'!G26/'V32'!$B$112)) * 100,"") -> 121.4096
C27: g32
C28: g33
C29: g34
C30: total | E30: =SUM(E26:E29) -> 679 | F30: =SUM(F26:F29) -> 16045.84 | G30: =SUM(G26:G29) -> 3514.3 | H30: =IFERROR(G30/F30,"") -> 0.21901627
B31: diff föreg V | E31: =IFERROR((E30-('V32'!E30))/('V32'!E30),"") -> 0.12417219 | F31: =IFERROR((F30-('V32'!F30))/('V32'!F30),"") -> 0.12407074 | G31: =IFERROR((G30-('V32'!G30))/('V32'!G30),"") -> 0.14295843 | H31: =IFERROR(H30-('V32'!H30),"") -> 0.003619302
B32: index | E32: =E30/$B$112 -> 0.036669007 | F32: =F30/$B$112 -> 0.86654642 | G32: =G30/$B$112 -> 0.18978776
B33: index diff % | E33: =IFERROR((E32-'V32'!E32)/'V32'!E32,"") -> 0.13449293 | F33: =IFERROR((F32-'V32'!F32)/'V32'!F32,"") -> 0.13439055 | G33: =IFERROR((G32-'V32'!G32)/'V32'!G32,"") -> 0.15345165
B34: Prestations Index | E34: =(E32 / AVERAGE('V25'!E32,'V26'!E32,'V27'!E32,'V28'!E32,'V29'!E32,'V30'!E32,'V31'!E32,'V32'!E32)) * 100 -> 122.18407 | F34: =(F32 / AVERAGE('V25'!F32,'V26'!F32,'V27'!F32,'V28'!F32,'V29'!F32,'V30'!F32,'V31'!F32,'V32'!F32)) * 100 -> 122.21373 | G34: =(G32 / AVERAGE('V25'!G32,'V26'!G32,'V27'!G32,'V28'!G32,'V29'!G32,'V30'!G32,'V31'!G32,'V32'!G32)) * 100 -> 121.4096 | H34: =IFERROR((G34*0.6)+(F34*0.4),"") -> 121.73125
A35: 4 | C35: Gavel 4 | D35: Vara | E35: Ant | F35: Förs | G35: BV | H35: B% | I35: idx antal | J35: idx förs | K35: idx BV
B36: KOMBI: 101648050 101625436 | C36: g41 | D36: Softlan Appear & Van | E36: 569 | F36: 13442.48 | G36: 2997.2 | H36: =IFERROR(G36/F36,"") -> 0.22296481 | I36: =IFERROR(((E36/$B$112) / AVERAGE('V25'!E36/'V25'!$B$112, 'V26'!E36/'V26'!$B$112, 'V27'!E36/'V27'!$B$112, 'V28'!E36/'V28'!$B$112, 'V29'!E36/'V29'!$B$112, 'V30'!E36/'V30'!$B$112, 'V31'!E36/'V31'!$B$112, 'V32'!E36/'V32'!$B$112)) * 100,"") -> 116.72275 | J36: =IFERROR(((F36/$B$112) / AVERAGE('V25'!F36/'V25'!$B$112, 'V26'!F36/'V26'!$B$112, 'V27'!F36/'V27'!$B$112, 'V28'!F36/'V28'!$B$112, 'V29'!F36/'V29'!$B$112, 'V30'!F36/'V30'!$B$112, 'V31'!F36/'V31'!$B$112, 'V32'!F36/'V32'!$B$112)) * 100,"") -> 116.73375 | K36: =IFERROR(((G36/$B$112) / AVERAGE('V25'!G36/'V25'!$B$112, 'V26'!G36/'V26'!$B$112, 'V27'!G36/'V27'!$B$112, 'V28'!G36/'V28'!$B$112, 'V29'!G36/'V29'!$B$112, 'V30'!G36/'V30'!$B$112, 'V31'!G36/'V31'!$B$112, 'V32'!G36/'V32'!$B$112)) * 100,"") -> 116.51413
C37: g42
C38: g43
C39: g44
C40: total | E40: =SUM(E36:E39) -> 569 | F40: =SUM(F36:F39) -> 13442.48 | G40: =SUM(G36:G39) -> 2997.2 | H40: =IFERROR(G40/F40,"") -> 0.22296481
B41: diff föreg V | E41: =IFERROR((E40-('V32'!E40))/('V32'!E40),"") -> 0.24235808 | F41: =IFERROR((F40-('V32'!F40))/('V32'!F40),"") -> 0.24237338 | G41: =IFERROR((G40-('V32'!G40))/('V32'!G40),"") -> 0.24143644 | H41: =IFERROR(H40-('V32'!H40),"") -> -0.00016827681
...

Sheet V34
A1: RANKING-APP
C3: vecka 34
C4: Vecka 34 | I4: 34 | J4: mot historik
A5: 1 | C5: Gavel 1 | D5: Vara | E5: Ant | F5: Förs | G5: BV | H5: B% | I5: idx antal | J5: idx förs | K5: idx BV
B6: KOMBI: 101712096 101625435 | C6: g11 | D6: A+ Cherry blossom | E6: 113 | F6: 8870.4 | G6: 1838.61 | H6: =IFERROR(G6/F6,"") -> 0.20727476 | I6: =IFERROR(((E6/$B$112) / AVERAGE('V25'!E6/'V25'!$B$112, 'V26'!E6/'V26'!$B$112, 'V27'!E6/'V27'!$B$112, 'V28'!E6/'V28'!$B$112, 'V29'!E6/'V29'!$B$112, 'V30'!E6/'V30'!$B$112, 'V31'!E6/'V31'!$B$112, 'V32'!E6/'V32'!$B$112, 'V33'!E6/'V33'!$B$112)) * 100,"") -> 86.63362 | J6: =IFERROR(((F6/$B$112) / AVERAGE('V25'!F6/'V25'!$B$112, 'V26'!F6/'V26'!$B$112, 'V27'!F6/'V27'!$B$112, 'V28'!F6/'V28'!$B$112, 'V29'!F6/'V29'!$B$112, 'V30'!F6/'V30'!$B$112, 'V31'!F6/'V31'!$B$112, 'V32'!F6/'V32'!$B$112, 'V33'!F6/'V33'!$B$112)) * 100,"") -> 94.700412 | K6: =IFERROR(((G6/$B$112) / AVERAGE('V25'!G6/'V25'!$B$112, 'V26'!G6/'V26'!$B$112, 'V27'!G6/'V27'!$B$112, 'V28'!G6/'V28'!$B$112, 'V29'!G6/'V29'!$B$112, 'V30'!G6/'V30'!$B$112, 'V31'!G6/'V31'!$B$112, 'V32'!G6/'V32'!$B$112, 'V33'!G6/'V33'!$B$112)) * 100,"") -> 89.090314
C7: g12
C8: g13
C9: g14
C10: total | E10: =SUM(E6:E9) -> 113 | F10: =SUM(F6:F9) -> 8870.4 | G10: =SUM(G6:G9) -> 1838.61 | H10: =IFERROR(G10/F10,"") -> 0.20727476
B11: diff föreg V | E11: =IFERROR((E10-('V33'!E10))/('V33'!E10),"") -> -0.30674847 | F11: =IFERROR((F10-('V33'!F10))/('V33'!F10),"") -> -0.24328714 | G11: =IFERROR((G10-('V33'!G10))/('V33'!G10),"") -> 0.88231741 | H11: =IFERROR(H10-('V33'!H10),"") -> 0.12394796
B12: index | E12: =E10/$B$112 -> 0.0064405814 | F12: =F10/$B$112 -> 0.50557994 | G12: =G10/$B$112 -> 0.10479396
B13: index diff % | E13: =IFERROR((E12-'V33'!E12)/'V33'!E12,"") -> -0.26834205 | F13: =IFERROR((F12-'V33'!F12)/'V33'!F12,"") -> -0.20136495 | G13: =IFERROR((G12-'V33'!G12)/'V33'!G12,"") -> 0.98659855
